<mujoco model="DualArmURDF">
  <compiler angle="radian" meshdir="../meshes/"/>

  <asset>
    <mesh name="Base_link" file="Base_link.STL"/>

    <mesh name="LeftShoulder_Link1" file="LeftShoulder_Link1.STL"/>
    <mesh name="LeftShoulder_Link2" file="LeftShoulder_Link2.STL"/>
    <mesh name="LeftShoulder_Link3" file="LeftShoulder_Link3.STL"/>
    <mesh name="LeftElbow_Link4" file="LeftElbow_Link4.STL"/>
    <mesh name="LeftWrist_Link5" file="LeftWrist_Link5.STL"/>
    <mesh name="LeftWrist_Link6" file="LeftWrist_Link6.STL"/>
    <mesh name="LeftWrist_Link7" file="LeftWrist_Link7.STL"/>
    
    <mesh name="RightShoulder_Link1" file="RightShoulder_Link1.STL"/>
    <mesh name="RightShoulder_Link2" file="RightShoulder_Link2.STL"/>
    <mesh name="RightShoulder_Link3" file="RightShoulder_Link3.STL"/>
    <mesh name="RightElbow_Link4" file="RightElbow_Link4.STL"/>
    <mesh name="RighWrist_Link5" file="RighWrist_Link5.STL"/>
    <mesh name="RightWrist_Link6" file="RightWrist_Link6.STL"/>
    <mesh name="RightWrist_Link7" file="RightWrist_Link7.STL"/>
  </asset>

  <worldbody>
    <body name="base_link" pos="0 0 0">
      <inertial pos="-0.0002 4e-05 -0.04522" quat="0.498303 0.499454 -0.500496 0.501741" mass="39.224"
          diaginertia="2.1654 1.4231 1.4209" />
      <geom type="mesh" contype="0" conaffinity="0" group="1" density="0" rgba="0.75294 0.75294 0.75294 1" mesh="Base_link"/>
      
      <body name="left_shoulder_pitch_link" pos="0 0.13275 1.125">
        <inertial pos="0.0024691 0.060922 -5.9756e-05" quat="0.70733 0.706849 -0.00492407 -0.00490418" mass="0.41079" diaginertia="0.000346622 0.00025915 0.000179428"/>
        <joint name="left_shoulder_pitch_joint" pos="0 0 0" axis="0 1 0" range="-6 6"/>
        <geom type="mesh" contype="0" conaffinity="0" group="1" density="0" rgba="0.75294 0.75294 0.75294 1" mesh="LeftShoulder_Link1"/>
        <geom type="mesh" rgba="0.75294 0.75294 0.75294 1" mesh="LeftShoulder_Link1"/>
        <body name="left_shoulder_roll_link" pos="0.042127 0.076002 -3.734e-05">
          <inertial pos="-0.035296 0.010378 -0.054088" quat="0.655563 0.215098 -0.206231 0.693858" mass="0.29343" diaginertia="0.000118751 0.000116328 9.87008e-05"/>
          <joint name="left_shoulder_roll_joint" pos="0 0 0" axis="1 0 0" range="-6 6"/>
          <geom type="mesh" contype="0" conaffinity="0" group="1" density="0" rgba="0.75294 0.75294 0.75294 1" mesh="LeftShoulder_Link2"/>
          <geom type="mesh" rgba="0.75294 0.75294 0.75294 1" mesh="LeftShoulder_Link2"/>
          <body name="left_shoulder_yaw_link" pos="-0.035 0.012525 -0.10778">
            <inertial pos="0.019703 0.0004755 -0.11177" quat="0.689854 -0.132336 -0.139452 0.697955" mass="0.35979" diaginertia="0.0002205 0.000183804 0.000104776"/>
            <joint name="left_shoulder_yaw_joint" pos="0 0 0" axis="0 0 1" range="-6 6"/>
            <geom type="mesh" contype="0" conaffinity="0" group="1" density="0" rgba="0.75294 0.75294 0.75294 1" mesh="LeftShoulder_Link3"/>
            <geom type="mesh" rgba="0.75294 0.75294 0.75294 1" mesh="LeftShoulder_Link3"/>
            <body name="left_elbow_link" pos="0.042 -0.026425 -0.1697">
              <inertial pos="0.079385 0.026419 -0.036184" quat="0.748777 -0.178992 -0.18913 0.609529" mass="0.32663" diaginertia="0.000115216 0.00011474 8.80683e-05"/>
              <joint name="left_elbow_joint" pos="0 0 0" axis="0 1 0" range="-6 6"/>
              <geom type="mesh" contype="0" conaffinity="0" group="1" density="0" rgba="0.75294 0.75294 0.75294 1" mesh="LeftElbow_Link4"/>
              <geom type="mesh" rgba="0.75294 0.75294 0.75294 1" mesh="LeftElbow_Link4"/>
              <body name="left_wrist_roll_link" pos="0.15175 0.026425 -0.042">
                <inertial pos="0.045783 4.8214e-05 -0.0054029" quat="-0.00422907 0.702113 -0.000907688 0.712052" mass="0.28348" diaginertia="0.000211417 0.000194722 7.81151e-05"/>
                <joint name="left_wrist_roll_joint" pos="0 0 0" axis="1 0 0" range="-6 6"/>
                <geom type="mesh" contype="0" conaffinity="0" group="1" density="0" rgba="0.75294 0.75294 0.75294 1" mesh="LeftWrist_Link5"/>
                <geom size="0.025 0.02" pos="0.045 0 0" type="cylinder" rgba="0.75294 0.75294 0.75294 1"/>
                <body name="left_wrist_yaw_link" pos="0.11575 0 -0.0299975">
                  <inertial pos="-3.1508e-05 0.0043496 0.029646" quat="0.69459 -0.00493516 0.0412762 0.718204" mass="0.13632" diaginertia="6.8357e-05 5.9565e-05 5.0938e-05"/>
                  <joint name="left_wrist_yaw_joint" pos="0 0 0" axis="0 0 1" range="-6 6"/>
                  <geom type="mesh" contype="0" conaffinity="0" group="1" density="0" rgba="0.75294 0.75294 0.75294 1" mesh="LeftWrist_Link6"/>
                  <geom size="0.025 0.015" pos="0 0 0.03" quat="0.707123 0.70709 0 0" type="cylinder" rgba="0.75294 0.75294 0.75294 1"/>
                  <body name="left_wrist_pitch_link" pos="0 0.02465 0.03">
                    <inertial pos="0.08169 -0.015776 -0.0018077" quat="0.435831 0.595332 -0.379538 0.558195" mass="0.22561" diaginertia="0.000128674 0.000118296 9.45361e-05"/>
                    <joint name="left_wrist_pitch_joint" pos="0 0 0" axis="0 1 0" range="-6 6"/>
                    <geom type="mesh" contype="0" conaffinity="0" group="1" density="0" rgba="1 1 1 1" mesh="LeftWrist_Link7"/>
                    <geom type="mesh" rgba="1 1 1 1" mesh="LeftWrist_Link7"/>
                  </body>
                </body>
              </body>
            </body>
          </body>
        </body>
      </body>

      <body name="right_shoulder_pitch_link" pos="0 -0.1324 1.125">
        <inertial pos="0.002467 -0.061272 -4.1086e-05" quat="0.706849 0.70733 0.00490419 0.00492406" mass="0.41079" diaginertia="0.000346622 0.00025915 0.000179428"/>
        <joint name="right_shoulder_pitch_joint" pos="0 0 0" axis="0 1 0" range="-6 6"/>
        <geom type="mesh" contype="0" conaffinity="0" group="1" density="0" rgba="0.75294 0.75294 0.75294 1" mesh="RightShoulder_Link1"/>
        <geom type="mesh" rgba="0.75294 0.75294 0.75294 1" mesh="RightShoulder_Link1"/>
        <body name="right_shoulder_roll_link" pos="0.042125 -0.076352 -1.867e-05">
          <inertial pos="-0.035296 -0.010378 -0.054088" quat="0.693858 -0.206231 0.215098 0.655563" mass="0.29343" diaginertia="0.000118751 0.000116328 9.87008e-05"/>
          <joint name="right_shoulder_roll_joint" pos="0 0 0" axis="1 0 0" range="-6 6"/>
          <geom type="mesh" contype="0" conaffinity="0" group="1" density="0" rgba="0.75294 0.75294 0.75294 1" mesh="RightShoulder_Link2"/>
          <geom type="mesh" rgba="0.75294 0.75294 0.75294 1" mesh="RightShoulder_Link2"/>
          <body name="right_shoulder_yaw_link" pos="-0.035 -0.012525 -0.10778">
            <inertial pos="0.019703 -0.00047549 -0.11177" quat="0.697955 -0.139452 -0.132336 0.689854" mass="0.35979" diaginertia="0.0002205 0.000183804 0.000104776"/>
            <joint name="right_shoulder_yaw_joint" pos="0 0 0" axis="0 0 1" range="-6 6"/>
            <geom type="mesh" contype="0" conaffinity="0" group="1" density="0" rgba="0.75294 0.75294 0.75294 1" mesh="RightShoulder_Link3"/>
            <geom type="mesh" rgba="0.75294 0.75294 0.75294 1" mesh="RightShoulder_Link3"/>
            <body name="right_elbow_link" pos="0.042 0.026425 -0.1697">
              <inertial pos="0.079385 -0.026419 -0.036184" quat="0.609529 -0.18913 -0.178992 0.748777" mass="0.32663" diaginertia="0.000115216 0.00011474 8.80683e-05"/>
              <joint name="right_elbow_joint" pos="0 0 0" axis="0 1 0" range="-6 6"/>
              <geom type="mesh" contype="0" conaffinity="0" group="1" density="0" rgba="0.75294 0.75294 0.75294 1" mesh="RightElbow_Link4"/>
              <geom type="mesh" rgba="0.75294 0.75294 0.75294 1" mesh="RightElbow_Link4"/>
              <body name="right_wrist_roll_link" pos="0.15175 -0.026425 -0.042">
                <inertial pos="0.045783 -4.8219e-05 -0.0054029" quat="0.0042289 0.702113 0.000907889 0.712052" mass="0.28348" diaginertia="0.000211417 0.000194722 7.81151e-05"/>
                <joint name="right_wrist_roll_joint" pos="0 0 0" axis="1 0 0" range="-6 6"/>
                <geom type="mesh" contype="0" conaffinity="0" group="1" density="0" rgba="0.75294 0.75294 0.75294 1" mesh="RighWrist_Link5"/>
                <geom size="0.025 0.02" pos="0.045 0 0" type="cylinder" rgba="0.75294 0.75294 0.75294 1"/>
                <body name="right_wrist_yaw_link" pos="0.11575 0 -0.029998">
                  <inertial pos="-3.1537e-05 -0.0043496 0.029646" quat="0.718208 0.0412721 -0.00493918 0.694585" mass="0.13632" diaginertia="6.8357e-05 5.9565e-05 5.0938e-05"/>
                  <joint name="right_wrist_yaw_joint" pos="0 0 0" axis="0 0 1" range="-6 6"/>
                  <geom type="mesh" contype="0" conaffinity="0" group="1" density="0" rgba="0.75294 0.75294 0.75294 1" mesh="RightWrist_Link6"/>
                  <geom size="0.025 0.015" pos="0 0 0.03" quat="0.707123 0.70709 0 0" type="cylinder" rgba="0.75294 0.75294 0.75294 1"/>
                  <body name="right_wrist_pitch_link" pos="0 -0.02465 0.03">
                    <inertial pos="0.08169 0.015776 -0.0018077" quat="0.595332 0.435831 -0.558195 0.379538" mass="0.22561" diaginertia="0.000128674 0.000118296 9.45361e-05"/>
                    <joint name="right_wrist_pitch_joint" pos="0 0 0" axis="0 1 0" range="-6 6"/>
                    <geom type="mesh" contype="0" conaffinity="0" group="1" density="0" rgba="0.89804 0.91765 0.92941 1" mesh="RightWrist_Link7"/>
                    <geom type="mesh" rgba="0.89804 0.91765 0.92941 1" mesh="RightWrist_Link7"/>
                  </body>
                </body>
              </body>
            </body>
          </body>
        </body>
      </body>
    </body>
  </worldbody>

  <actuator>
    <position name="left_shoulder_pitch_joint" joint="left_shoulder_pitch_joint" />
    <position name="left_shoulder_roll_joint" joint="left_shoulder_roll_joint" />
    <position name="left_shoulder_yaw_joint" joint="left_shoulder_yaw_joint" />
    <position name="left_elbow_joint" joint="left_elbow_joint" />
    <position name="left_wrist_roll_joint" joint="left_wrist_roll_joint" />
    <position name="left_wrist_yaw_joint" joint="left_wrist_yaw_joint" />
    <position name="left_wrist_pitch_joint" joint="left_wrist_pitch_joint" />

    <position name="right_shoulder_pitch_joint" joint="right_shoulder_pitch_joint" />
    <position name="right_shoulder_roll_joint" joint="right_shoulder_roll_joint" />
    <position name="right_shoulder_yaw_joint" joint="right_shoulder_yaw_joint" />
    <position name="right_elbow_joint" joint="right_elbow_joint" />
    <position name="right_wrist_roll_link" joint="right_wrist_roll_joint" />
    <position name="right_wrist_yaw_joint" joint="right_wrist_yaw_joint" />
    <position name="right_wrist_pitch_joint" joint="right_wrist_pitch_joint" />
  </actuator>
</mujoco>
